<?xml version="1.0" ?>
<robot xmlns:xacro="http://www.ros.org/wiki/xacro">
    
    <link
        name="m_base">
        <inertial>
            <origin
                xyz="-3.4809E-08 -0.05038 0.0010533"
                rpy="0 0 0" />
            <mass
                value="1.5121" />
            <inertia
                ixx="0.0006372"
                ixy="2.6122E-09"
                ixz="1.9384E-10"
                iyy="0.00027925"
                iyz="0.00011021"
                izz="0.00064253" />
        </inertial>
        <visual>
            <origin
                xyz="0 0 0"
                rpy="0 0 0" />
            <geometry>
                <mesh
                    filename="package://mobile_description/meshes/m_base.STL" />
            </geometry>
            <material
                name="">
                <color
                    rgba="0.75294 0.75294 0.75294 1" />
            </material>
        </visual>
        <collision>
            <origin
                xyz="0 0 0"
                rpy="0 0 0" />
            <geometry>
                <mesh
                    filename="package://mobile_description/meshes/m_base.STL" />
            </geometry>
        </collision>
    </link>
    <joint name="m_joint_base" type="fixed">
        <parent link="chassis"/>
        <child link="m_base"/>
        <origin 
            xyz="${0.135/2-0.01} 0 ${0.145+0.0165/2-0.005}" 
            rpy="0 0 ${-PI/2}"/>
        <axis xyz="0 0 0"/>
        <limit effort="0" velocity="0"/>
    </joint>
    <link
        name="m_link_1">
        <inertial>
            <origin
                xyz="5.3086E-06 -0.0050977 0.025693"
                rpy="0 0 0" />
            <mass
                value="0.53016" />
            <inertia
                ixx="0.0013772"
                ixy="1.2464E-07"
                ixz="6.5275E-08"
                iyy="0.000284"
                iyz="5.4578E-05"
                izz="0.0010934" />
        </inertial>
        <visual>
            <origin
                xyz="0 0 0"
                rpy="0 0 0" />
            <geometry>
                <mesh
                    filename="package://mobile_description/meshes/m_link_1.STL" />
            </geometry>
            <material
                name="">
                <color
                    rgba="0.75294 0.75294 0.75294 1" />
            </material>
        </visual>
        <collision>
            <origin
                xyz="0 0 0"
                rpy="0 0 0" />
            <geometry>
                <mesh
                    filename="package://mobile_description/meshes/m_link_1.STL" />
            </geometry>
        </collision>
    </link>
    <joint
        name="m_joint_1"
        type="revolute">
        <origin
            xyz="0 0 0.018"
            rpy="9.5272E-17 2.5487E-17 -1.5708" />
        <parent
            link="m_base" />
        <child
            link="m_link_1" />
        <axis
            xyz="0 0 1" />
        <limit 
            effort="10.0"
            velocity="1.0"
            lower="${-1.60}"
            upper="${1.60}" />

    </joint>
    <link
        name="m_link_2">
        <inertial>
            <origin
                xyz="0.12595 0.00091717 -0.005421"
                rpy="0 0 0" />
            <mass
                value="0.33957" />
            <inertia
                ixx="0.00053588"
                ixy="8.0811E-06"
                ixz="0.00037406"
                iyy="0.0014491"
                iyz="-4.6471E-06"
                izz="0.00095056" />
        </inertial>
        <visual>
            <origin
                xyz="0 0 0"
                rpy="0 0 0" />
            <geometry>
                <mesh
                    filename="package://mobile_description/meshes/m_link_2.STL" />
            </geometry>
            <material
                name="">
                <color
                    rgba="0.75294 0.75294 0.75294 1" />
            </material>
        </visual>
        <collision>
            <origin
                xyz="0 0 0"
                rpy="0 0 0" />
            <geometry>
                <mesh
                    filename="package://mobile_description/meshes/m_link_2.STL" />
            </geometry>
        </collision>
    </link>
    <joint
        name="m_joint_2"
        type="revolute">
        <origin
            xyz="0 0 0.055"
            rpy="1.5708 -1.5708 0" />
        <parent
            link="m_link_1" />
        <child
            link="m_link_2" />
        <axis
            xyz="0 0 1" />
        <limit 
            effort="10.0"
            velocity="1.0"
            lower="${-3.14}"
            upper="${3.14}"/>
    </joint>
    <link
        name="m_link_3">
        <inertial>
            <origin
                xyz="0.12805 0.00074276 -0.0046757"
                rpy="0 0 0" />
            <mass
                value="0.32588" />
            <inertia
                ixx="0.00038507"
                ixy="6.7854E-06"
                ixz="0.00031809"
                iyy="0.0012115"
                iyz="-3.4316E-06"
                izz="0.0008557" />
        </inertial>
        <visual>
            <origin
                xyz="0 0 0"
                rpy="0 0 0" />
            <geometry>
                <mesh
                    filename="package://mobile_description/meshes/m_link_3.STL" />
            </geometry>
            <material
                name="">
                <color
                    rgba="0.75294 0.75294 0.75294 1" />
            </material>
        </visual>
        <collision>
            <origin
                xyz="0 0 0"
                rpy="0 0 0" />
            <geometry>
                <mesh
                    filename="package://mobile_description/meshes/m_link_3.STL" />
            </geometry>
        </collision>
    </link>
    <joint
        name="m_joint_3"
        type="revolute">
        <origin
            xyz="0.2 0 0"
            rpy="4.4409E-16 4.5852E-16 -1.7798E-16" />
        <parent
            link="m_link_2" />
        <child
            link="m_link_3" />
        <axis
            xyz="0 0 1" />
        <limit 
            effort="10.0"
            velocity="1.0"
            lower="${-3.14}"
            upper="${3.14}"/>
    </joint>
    <link
        name="m_link_4">
        <inertial>
            <origin
                xyz="0.042624 1.8551E-17 0.0094381"
                rpy="0 0 0" />
            <mass
                value="0.18491" />
            <inertia
                ixx="9.4388E-07"
                ixy="-1.361E-20"
                ixz="-2.8787E-07"
                iyy="4.3712E-05"
                iyz="-9.3643E-23"
                izz="4.2768E-05" />
        </inertial>
        <visual>
            <origin
                xyz="0 0 0"
                rpy="0 0 0" />
            <geometry>
                <mesh
                    filename="package://mobile_description/meshes/m_link_4.STL" />
            </geometry>
            <material
                name="">
                <color
                    rgba="0.75294 0.75294 0.75294 1" />
            </material>
        </visual>
        <collision>
            <origin
                xyz="0 0 0"
                rpy="0 0 0" />
            <geometry>
                <mesh
                    filename="package://mobile_description/meshes/m_link_4.STL" />
            </geometry>
        </collision>
    </link>
    <joint
        name="m_joint_4"
        type="revolute">
        <origin
            xyz="0.2 0 0"
            rpy="-3.3307E-16 -6.6356E-16 -1.9531E-16" />
        <parent
            link="m_link_3" />
        <child
            link="m_link_4" />
        <axis
            xyz="0 0 1" />
        <limit 
            effort="10.0"
            velocity="1.0"
            lower="${-3.14}"
            upper="${3.14}"/>
    </joint>
    <!-- <link
        name="m_link_gripper">
        <inertial>
            <origin
                xyz="-0.0069546 0.0010309 -0.036727"
                rpy="0 0 0" />
            <mass
                value="0.098787" />
            <inertia
                ixx="5.8957E-05"
                ixy="1.4882E-06"
                ixz="5.6679E-06"
                iyy="6.3174E-05"
                iyz="-4.7843E-07"
                izz="2.5215E-05" />
        </inertial>
        <visual>
            <origin
                xyz="0 0 0"
                rpy="0 0 0" />
            <geometry>
                <mesh
                    filename="package://mobile_description/meshes/m_link_gripper.STL" />
            </geometry>
            <material
                name="">
                <color
                    rgba="0.75294 0.75294 0.75294 1" />
            </material>
        </visual>
        <collision>
            <origin
                xyz="0 0 0"
                rpy="0 0 0" />
            <geometry>
                <mesh
                    filename="package://mobile_description/meshes/m_link_gripper.STL" />
            </geometry>
        </collision>
    </link> -->
    <!-- <joint
        name="m_joint_5"
        type="revolute">
        <origin
            xyz="0.0895 0 0.0095"
            rpy="1.5708 3.861E-32 -1.5708" />
        <parent
            link="m_link_4" />
        <child
            link="m_link_gripper" />
        <axis
            xyz="0 0 1" />
        <limit 
            effort="10.0"
            velocity="1.0"
            lower="${-3.14}"
            upper="${3.14}"/>
    </joint> -->
    <link name="m_link_gripper">
        <visual>
            <origin 
                xyz="0 0 0"
                rpy="0 0 0 "/>
            <geometry>
                <box size="0.08 0.01 0.01"/>
            </geometry>
            <material name="orange"/>
        </visual>
        <collision>
            <origin 
                xyz="0 0 0"
                rpy="0 0 0 "/>
            <geometry>
                <box size="0.08 0.01 0.01"/>
            </geometry>
        </collision>
        <inertial>
            <origin 
                xyz = "0 0 0"
                rpy = "0 0 0"/>
            <mass 
                value="0.05"/>
            <inertia 
                ixx="0.000004" 
                ixy="0.0" 
                ixz="0.0"
                iyy="0.00001" 
                iyz="0.0" 
                izz="0.00001"/>
        </inertial>
    </link>
    <joint
        name="m_joint_5"
        type="revolute">
        <origin
            xyz="0.1 0 0.01"
            rpy="0 ${3.14/2} 0" />
        <parent
            link="m_link_4" />
        <child
            link="m_link_gripper"/>
        <axis
            xyz="0 0 1" />
        <limit 
            effort="10.0"
            velocity="1.0"
            lower="${-3.14}"
            upper="${3.14}"/>
    </joint>
    <link name="gripper_finger_left">
        <visual>
            <origin 
                xyz="-0.035 0 0.045"
                rpy="0 ${3.14/2} 0"/>
            <geometry>
                <box size="0.08 0.01 0.01"/>
            </geometry>
            <material name="orange"/>
        </visual>
        <collision>
            <origin 
                xyz="-0.035 0 0.045"
                rpy="0 ${3.14/2} 0"/>
            <geometry>
                <box size="0.08 0.01 0.01"/>
            </geometry>
        </collision>
        <inertial>
            <origin 
                xyz="-0.035 0 0.045"
                rpy="0 0 0" />
            <mass 
                value="0.05"/>
            <inertia 
                ixx="0.0001" 
                ixy="0.0" 
                ixz="0.0"
                iyy="0.00001" 
                iyz="0.0" 
                izz="0.00001"/>
        </inertial>
    </link>
    <joint name="finger_joint_1" type="prismatic">
        <parent 
            link="m_link_gripper"/>
        <child 
            link="gripper_finger_left"/>
        <origin 
            xyz="0 0 0"
            rpy="0 0 0"/>
        <axis 
            xyz="1 0 0"/>
        <limit 
            effort="10" lower="0" upper="0.03" velocity="1.0"/>
        <dynamics damping="50" friction="1"/>
    </joint>
     <link name="gripper_finger_right">
        <visual>
            <origin 
                xyz="0.035 0 0.045"
                rpy="0 ${3.14/2} 0"/>
            <geometry>
                <box size="0.08 0.01 0.01"/>
            </geometry>
            <material name="orange"/>
        </visual>
        <collision>
            <origin 
                xyz="0.035 0 0.045"
                rpy="0 ${3.14/2} 0"/>
            <geometry>
                <box size="0.08 0.01 0.01"/>
            </geometry>
        </collision>
        <inertial>
            <origin 
                xyz="0.035 0 0.045"
                rpy="0 0 0" />
            <mass 
                value="0.05"/>
            <inertia 
                ixx="0.00001" 
                ixy="0.0" 
                ixz="0.0"
                iyy="0.00001" 
                iyz="0.0" 
                izz="0.0001"/>
        </inertial>
    </link>
     <joint name="finger_joint_2" type="prismatic">
        <parent 
            link="m_link_gripper"/>
        <child 
            link="gripper_finger_right"/>
        <origin 
            xyz="0 0 0"/>
        <axis 
            xyz="1 0 0"/>
        <limit 
            effort="10.0" lower="-0.03" upper="0" velocity="1.0"/>
    </joint>

    <!-- Arm @ Gazebo -->
    <xacro:include filename="$(find mobile_description)/urdf/arm.gazebo" />

</robot>

<!-- <inertia
    ixx="1.0"
    ixy="0.0"
    ixz="0.0"
    iyy="1.0"
    iyz="0.0"
    izz="1.0" /> -->
